<?xml version="1.0"?>

<robot xmlns:xacro="http://www.ros.org/wiki/xacro">

  <!-- Base -->
  <xacro:macro name="wheel"  params="robot_name prefix side *joint_pose">

    <link name="${robot_name}_${prefix}_${side}_wheel_link">
      <visual>
        <origin xyz="0 0 0" rpy="${PI/2} 0 0"/>
        <geometry>
          <mesh filename="package://ridgeback_description/meshes/wheel.stl"/>
        </geometry>
        <material name="black" />
      </visual>
      <collision>
        <origin xyz="0 0 0" rpy="${PI/2} 0 0"/>
        <geometry>
          <cylinder radius="${wheel_radius}" length="${wheel_width}"/>
        </geometry>
      </collision>
      <inertial>
        <origin xyz="0 0 0" rpy="0 0 0"/>
        <mass value="2.3"/>
        <inertia
          ixx="3.3212e-3" ixy="0" ixz="0"
          iyy="6.6424e-3" iyz="0"
          izz="3.3212e-3"/>
      </inertial>
    </link>

    <joint name="${robot_name}_${prefix}_${side}_wheel" type="continuous">
      <parent link="${robot_name}_${prefix}_rocker_link"/>
      <child link="${robot_name}_${prefix}_${side}_wheel_link" />
      <xacro:insert_block name="joint_pose" />
      <axis xyz="0 1 0" />
    </joint>

    <transmission name="${robot_name}_${prefix}_wheel_trans">
      <type>transmission_interface/SimpleTransmission</type>
      <joint name="${robot_name}_${prefix}_${side}_wheel">
        <hardwareInterface>hardware_interface/VelocityJointInterface</hardwareInterface>
      </joint>
      <actuator name="${robot_name}_${prefix}_${side}_actuator">
        <mechanicalReduction>1</mechanicalReduction>
      </actuator>
    </transmission>
  </xacro:macro>

</robot>
